#VRML_SIM R2025a utf8

EXTERNPROTO "https://raw.githubusercontent.com/cyberbotics/webots/R2023b/projects/objects/backgrounds/protos/TexturedBackground.proto"
EXTERNPROTO "https://raw.githubusercontent.com/cyberbotics/webots/R2023b/projects/objects/backgrounds/protos/TexturedBackgroundLight.proto"
EXTERNPROTO "https://raw.githubusercontent.com/cyberbotics/webots/R2023b/projects/objects/floors/protos/Floor.proto"

WorldInfo {
  basicTimeStep 2
  contactProperties [
    ContactProperties {
      material1 "solid"
      material2 "floor"
      coulombFriction [
        3
      ]
    }
  ]
}
Viewpoint {
  orientation 0.21733554777997066 0.2496963496701552 -0.9436190929779767 1.401318338654304
  position -1.788479604008232 3.275590434023513 1.4215824237413568
}
TexturedBackground {
}
TexturedBackgroundLight {
}
Floor {
}
Robot {
  translation -0.009878549018939297 0.02038574313330772 0.28947242448089233
  rotation 0.004949651276201862 -0.0007549448472520941 0.999987465426703 2.889205454167719
  children [
    InertialUnit {
      name "imu"
    }
    HingeJoint {
      jointParameters HingeJointParameters {
        position 0.4985831537145407
        axis 0 1 0
        anchor 0.2 0.1 0
        minStop -1.5
        maxStop 1.5
      }
      device [
        PositionSensor {
          name "sensor_FL_hip"
        }
        RotationalMotor {
          name "motor_FL_hip"
          maxTorque 100
        }
      ]
      endPoint Solid {
        translation 0.1522317705994842 0.10001502745056146 -0.0877347534401482
        rotation 1.9403074568940382e-05 0.999999999793701 -6.009907025555596e-06 0.4985820197081742
        children [
          HingeJoint {
            jointParameters HingeJointParameters {
              position -1.522583392178559
              axis 0 1 0
              anchor 0 0 -0.1
              minStop -2.5
            }
            device [
              PositionSensor {
                name "sensor_FL_knee"
              }
              RotationalMotor {
                name "motor_FL_knee"
                maxTorque 100
              }
            ]
            endPoint Solid {
              translation 0.0998837981540453 0 -0.10481942593245619
              rotation 0 -0.9999999999999999 0 1.522583392178559
              children [
                Shape {
                  appearance PBRAppearance {
                    baseColor 1 0 0
                  }
                  geometry Cylinder {
                    height 0.2
                    radius 0.015
                  }
                }
              ]
              boundingObject Shape {
                geometry Cylinder {
                  height 0.2
                  radius 0.015
                }
              }
              physics Physics {
                density -1
                mass 0.5
              }
            }
          }
          Shape {
            appearance PBRAppearance {
              baseColor 1 0 0
              baseColorMap ImageTexture {
              }
            }
            geometry Cylinder {
              height 0.2
              radius 0.02
            }
          }
        ]
        name "FL"
        boundingObject Shape {
          geometry Cylinder {
            height 0.2
            radius 0.02
          }
        }
        physics Physics {
          density -1
          mass 1
        }
      }
    }
    HingeJoint {
      jointParameters HingeJointParameters {
        position 1.0221834356306134
        axis 0 1 0
        anchor -0.2 -0.1 0
        minStop -1.5
        maxStop 1.5
      }
      device [
        PositionSensor {
          name "sensor_BR_hip"
        }
        RotationalMotor {
          name "motor_BR_hip"
          maxTorque 100
        }
      ]
      endPoint Solid {
        translation -0.2852564085354914 -0.10000001472150344 -0.052108544197472656
        rotation 8.853715148201564e-06 0.9999999999453221 -5.564866634225424e-06 1.0221824710589629
        children [
          HingeJoint {
            jointParameters HingeJointParameters {
              position -1.522322365882863
              axis 0 1 0
              anchor 0 0 -0.1
              minStop -2.5
            }
            device [
              PositionSensor {
                name "sensor_BR_knee"
              }
              RotationalMotor {
                name "motor_BR_knee"
                maxTorque 100
              }
            ]
            endPoint Solid {
              translation 0.09988253675890324 0 -0.10484549797301482
              rotation 0 -1 0 1.522322365882863
              children [
                Shape {
                  appearance PBRAppearance {
                    baseColor 1 0 0
                  }
                  geometry Cylinder {
                    height 0.2
                    radius 0.015
                  }
                }
              ]
              boundingObject Shape {
                geometry Cylinder {
                  height 0.2
                  radius 0.015
                }
              }
              physics Physics {
                density -1
                mass 0.5
              }
            }
          }
          Shape {
            appearance PBRAppearance {
              baseColor 1 0 0
            }
            geometry Cylinder {
              height 0.2
              radius 0.02
            }
          }
        ]
        name "BR"
        boundingObject Shape {
          geometry Cylinder {
            height 0.2
            radius 0.02
          }
        }
        physics Physics {
          density -1
          mass 1
        }
      }
    }
    HingeJoint {
      jointParameters HingeJointParameters {
        position 1.0225897572969511
        axis 0 1 0
        anchor -0.2 0.1 0
        minStop -1.5
        maxStop 1.5
      }
      device [
        PositionSensor {
          name "sensor_BL_hip"
        }
        RotationalMotor {
          name "motor_BL_hip"
          maxTorque 100
        }
      ]
      endPoint Solid {
        translation -0.285260438514856 0.0999999899577868 -0.05206343141637724
        rotation 8.66623734835676e-06 0.9999999999475307 -5.462132705982172e-06 1.0225886211623638
        children [
          HingeJoint {
            jointParameters HingeJointParameters {
              position -1.5224276256505767
              axis 0 1 0
              anchor 0 0 -0.1
              minStop -2.5
            }
            device [
              PositionSensor {
                name "sensor_BL_knee"
              }
              RotationalMotor {
                name "motor_BL_knee"
                maxTorque 100
              }
            ]
            endPoint Solid {
              translation 0.09988304624156116 0 -0.10483498433357313
              rotation 0 -1 0 1.5224276256505769
              children [
                Shape {
                  appearance PBRAppearance {
                    baseColor 1 0 0
                  }
                  geometry Cylinder {
                    height 0.2
                    radius 0.015
                  }
                }
              ]
              boundingObject Shape {
                geometry Cylinder {
                  height 0.2
                  radius 0.015
                }
              }
              physics Physics {
                density -1
                mass 0.5
              }
            }
          }
          Shape {
            appearance PBRAppearance {
              baseColor 1 0 0
            }
            geometry Cylinder {
              height 0.2
              radius 0.02
            }
          }
        ]
        name "BL"
        boundingObject Shape {
          geometry Cylinder {
            height 0.2
            radius 0.02
          }
        }
        physics Physics {
          density -1
          mass 1
        }
      }
    }
    HingeJoint {
      jointParameters HingeJointParameters {
        position 0.4985125926717406
        axis 0 1 0
        anchor 0.2 -0.1 0
        minStop -1.5
        maxStop 1.5
      }
      device [
        PositionSensor {
          name "sensor_FR_hip"
        }
        RotationalMotor {
          name "motor_FR_hip"
          maxTorque 100
        }
      ]
      endPoint Solid {
        translation 0.15223277244215033 -0.10000002447426948 -0.08774724611521537
        rotation 1.938550731885755e-05 0.9999999997940753 -6.004314676602153e-06 0.4985114506636355
        children [
          HingeJoint {
            jointParameters HingeJointParameters {
              position -1.5223231116171585
              axis 0 1 0
              anchor 0 0 -0.1
              minStop -2.5
            }
            device [
              PositionSensor {
                name "sensor_FR_knee"
              }
              RotationalMotor {
                name "motor_FR_knee"
                maxTorque 100
              }
            ]
            endPoint Solid {
              translation 0.09988254037232869 0 -0.10484542348718029
              rotation 0 -1 0 1.5223231116171585
              children [
                Shape {
                  appearance PBRAppearance {
                    baseColor 1 0 0
                  }
                  geometry Cylinder {
                    height 0.2
                    radius 0.015
                  }
                }
              ]
              boundingObject Shape {
                geometry Cylinder {
                  height 0.2
                  radius 0.015
                }
              }
              physics Physics {
                density -1
                mass 0.5
              }
            }
          }
          Shape {
            appearance PBRAppearance {
              baseColor 1 0 0
            }
            geometry Cylinder {
              height 0.2
              radius 0.02
            }
          }
        ]
        name "FR"
        boundingObject Shape {
          geometry Cylinder {
            height 0.2
            radius 0.02
          }
        }
        physics Physics {
          density -1
          mass 1
        }
      }
    }
    Shape {
      appearance PBRAppearance {
        baseColor 0 0 0.498039
      }
      geometry Box {
        size 0.4 0.2 0.1
      }
    }
  ]
  boundingObject Shape {
    appearance PBRAppearance {
    }
    geometry Box {
      size 0.4 0.2 0.1
    }
  }
  physics Physics {
    density -1
    mass 5
  }
  controller "main_SMC_controller"
}
