#VRML_SIM R2025a utf8

EXTERNPROTO "https://raw.githubusercontent.com/cyberbotics/webots/R2023b/projects/objects/backgrounds/protos/TexturedBackground.proto"
EXTERNPROTO "https://raw.githubusercontent.com/cyberbotics/webots/R2023b/projects/objects/backgrounds/protos/TexturedBackgroundLight.proto"
EXTERNPROTO "https://raw.githubusercontent.com/cyberbotics/webots/R2023b/projects/objects/floors/protos/Floor.proto"

WorldInfo {
  basicTimeStep 2
  contactProperties [
    ContactProperties {
      material1 "solid"
      material2 "floor"
      coulombFriction [
        3
      ]
    }
  ]
}
Viewpoint {
  orientation 0.1950024508843732 -0.14902241504471098 -0.9694154754094497 4.325685269484337
  position 3.777068802779845 -8.817626610642375 4.137103978858347
}
TexturedBackground {
}
TexturedBackgroundLight {
}
Floor {
}
Robot {
  translation -4 0 0.289472
  children [
    InertialUnit {
      name "imu"
    }
    HingeJoint {
      jointParameters HingeJointParameters {
        position 1.0480470059528115
        axis 0 1 0
        anchor 0.2 0.1 0
        minStop -1.5
        maxStop 1.5
      }
      device [
        PositionSensor {
          name "sensor_FL_hip"
        }
        RotationalMotor {
          name "motor_FL_hip"
          maxTorque 100
        }
      ]
      endPoint Solid {
        translation 0.11344530561699077 0.10001502745056146 -0.04987459856006508
        rotation 8.40440628500831e-06 0.9999999999498446 -5.447634839729882e-06 1.0480458718912549
        children [
          HingeJoint {
            jointParameters HingeJointParameters {
              position -1.7846711134921627
              axis 0 1 0
              anchor 0 0 -0.1
              minStop -2.5
            }
            device [
              PositionSensor {
                name "sensor_FL_knee"
              }
              RotationalMotor {
                name "motor_FL_knee"
                maxTorque 100
              }
            ]
            endPoint Solid {
              translation 0.0977215837240373 0 -0.07877520142704629
              rotation 0 -1 0 1.7846711134921627
              children [
                Shape {
                  appearance PBRAppearance {
                    baseColor 1 0 0
                  }
                  geometry Cylinder {
                    height 0.2
                    radius 0.015
                  }
                }
              ]
              boundingObject Shape {
                geometry Cylinder {
                  height 0.2
                  radius 0.015
                }
              }
              physics Physics {
                density -1
                mass 0.5
              }
            }
          }
          Shape {
            appearance PBRAppearance {
              baseColor 1 0 0
              baseColorMap ImageTexture {
              }
            }
            geometry Cylinder {
              height 0.2
              radius 0.02
            }
          }
        ]
        name "FL"
        boundingObject Shape {
          geometry Cylinder {
            height 0.2
            radius 0.02
          }
        }
        physics Physics {
          density -1
          mass 1
        }
      }
    }
    HingeJoint {
      jointParameters HingeJointParameters {
        position 1.0502766846069578
        axis 0 1 0
        anchor -0.2 -0.1 0
        minStop -1.5
        maxStop 1.5
      }
      device [
        PositionSensor {
          name "sensor_BR_hip"
        }
        RotationalMotor {
          name "motor_BR_hip"
          maxTorque 100
        }
      ]
      endPoint Solid {
        translation -0.28668647301791983 -0.10000001472150344 -0.049693168247396176
        rotation 8.561091612953971e-06 0.9999999999479513 -5.55020981564758e-06 1.0502757200338084
        children [
          HingeJoint {
            jointParameters HingeJointParameters {
              position -1.788807905086149
              axis 0 1 0
              anchor 0 0 -0.1
              minStop -2.5
            }
            device [
              PositionSensor {
                name "sensor_BR_knee"
              }
              RotationalMotor {
                name "motor_BR_knee"
                maxTorque 100
              }
            ]
            endPoint Solid {
              translation 0.09763294523034685 0 -0.07837113027344389
              rotation 0 -0.9999999999999999 0 1.788807905086149
              children [
                Shape {
                  appearance PBRAppearance {
                    baseColor 1 0 0
                  }
                  geometry Cylinder {
                    height 0.2
                    radius 0.015
                  }
                }
              ]
              boundingObject Shape {
                geometry Cylinder {
                  height 0.2
                  radius 0.015
                }
              }
              physics Physics {
                density -1
                mass 0.5
              }
            }
          }
          Shape {
            appearance PBRAppearance {
              baseColor 1 0 0
            }
            geometry Cylinder {
              height 0.2
              radius 0.02
            }
          }
        ]
        name "BR"
        boundingObject Shape {
          geometry Cylinder {
            height 0.2
            radius 0.02
          }
        }
        physics Physics {
          density -1
          mass 1
        }
      }
    }
    HingeJoint {
      jointParameters HingeJointParameters {
        position 0.7295018194275887
        axis 0 1 0
        anchor -0.2 0.1 0
        minStop -1.5
        maxStop 1.5
      }
      device [
        PositionSensor {
          name "sensor_BL_hip"
        }
        RotationalMotor {
          name "motor_BL_hip"
          maxTorque 100
        }
      ]
      endPoint Solid {
        translation -0.2665829800298295 0.0999999899577868 -0.07447583525507236
        rotation 1.285407880410347e-05 0.9999999999012763 -5.67627974696685e-06 0.7295006833140201
        children [
          HingeJoint {
            jointParameters HingeJointParameters {
              position -1.7889678020114004
              axis 0 1 0
              anchor 0 0 -0.1
              minStop -2.5
            }
            device [
              PositionSensor {
                name "sensor_BL_knee"
              }
              RotationalMotor {
                name "motor_BL_knee"
                maxTorque 100
              }
            ]
            endPoint Solid {
              translation 0.09762948559250052 0 -0.07835551934225854
              rotation 0 -0.9999999999999999 0 1.7889678020114006
              children [
                Shape {
                  appearance PBRAppearance {
                    baseColor 1 0 0
                  }
                  geometry Cylinder {
                    height 0.2
                    radius 0.015
                  }
                }
              ]
              boundingObject Shape {
                geometry Cylinder {
                  height 0.2
                  radius 0.015
                }
              }
              physics Physics {
                density -1
                mass 0.5
              }
            }
          }
          Shape {
            appearance PBRAppearance {
              baseColor 1 0 0
            }
            geometry Cylinder {
              height 0.2
              radius 0.02
            }
          }
        ]
        name "BL"
        boundingObject Shape {
          geometry Cylinder {
            height 0.2
            radius 0.02
          }
        }
        physics Physics {
          density -1
          mass 1
        }
      }
    }
    HingeJoint {
      jointParameters HingeJointParameters {
        position 0.7316855138223484
        axis 0 1 0
        anchor 0.2 -0.1 0
        minStop -1.5
        maxStop 1.5
      }
      device [
        PositionSensor {
          name "sensor_FR_hip"
        }
        RotationalMotor {
          name "motor_FR_hip"
          maxTorque 100
        }
      ]
      endPoint Solid {
        translation 0.1332500603145892 -0.10000002447426948 -0.0743352727940205
        rotation 1.2795235749205688e-05 0.9999999999020823 -5.667221694327559e-06 0.7316843717812086
        children [
          HingeJoint {
            jointParameters HingeJointParameters {
              position -1.7940988830046642
              axis 0 1 0
              anchor 0 0 -0.1
              minStop -2.5
            }
            device [
              PositionSensor {
                name "sensor_FR_knee"
              }
              RotationalMotor {
                name "motor_FR_knee"
                maxTorque 100
              }
            ]
            endPoint Solid {
              translation 0.09751714130517314 0 -0.07785486166972791
              rotation 0 -1 0 1.7940988830046642
              children [
                Shape {
                  appearance PBRAppearance {
                    baseColor 1 0 0
                  }
                  geometry Cylinder {
                    height 0.2
                    radius 0.015
                  }
                }
              ]
              boundingObject Shape {
                geometry Cylinder {
                  height 0.2
                  radius 0.015
                }
              }
              physics Physics {
                density -1
                mass 0.5
              }
            }
          }
          Shape {
            appearance PBRAppearance {
              baseColor 1 0 0
            }
            geometry Cylinder {
              height 0.2
              radius 0.02
            }
          }
        ]
        name "FR"
        boundingObject Shape {
          geometry Cylinder {
            height 0.2
            radius 0.02
          }
        }
        physics Physics {
          density -1
          mass 1
        }
      }
    }
    Shape {
      appearance PBRAppearance {
        baseColor 0 0 0.498039
      }
      geometry Box {
        size 0.4 0.2 0.1
      }
    }
  ]
  boundingObject Shape {
    appearance PBRAppearance {
    }
    geometry Box {
      size 0.4 0.2 0.1
    }
  }
  physics Physics {
    density -1
    mass 5
  }
  controller "main_SMC_controller"
}
