#VRML_SIM R2025a utf8

EXTERNPROTO "https://raw.githubusercontent.com/cyberbotics/webots/R2023b/projects/objects/backgrounds/protos/TexturedBackground.proto"
EXTERNPROTO "https://raw.githubusercontent.com/cyberbotics/webots/R2023b/projects/objects/backgrounds/protos/TexturedBackgroundLight.proto"
EXTERNPROTO "https://raw.githubusercontent.com/cyberbotics/webots/R2023b/projects/objects/floors/protos/Floor.proto"

WorldInfo {
  basicTimeStep 2
  contactProperties [
    ContactProperties {
      material1 "solid"
      material2 "floor"
      coulombFriction [
        3
      ]
    }
  ]
}
Viewpoint {
  orientation 0.24033863172337402 -0.2514071066983295 -0.9375669623034458 4.619216826792138
  position -2.8204795346842664 -3.299253739973494 1.6822351871549817
}
TexturedBackground {
}
TexturedBackgroundLight {
}
Floor {
}
Robot {
  translation -4.000960066469215 -0.002794033035989883 0.26208089862674555
  rotation 0.8811327879339883 -0.4728069867196682 -0.007652668602812827 0.011770703108016969
  children [
    InertialUnit {
      name "imu"
    }
    HingeJoint {
      jointParameters HingeJointParameters {
        position 1.0442523917296898
        axis 0 1 0
        anchor 0.2 0.1 0
        minStop -1.5
        maxStop 1.5
      }
      device [
        PositionSensor {
          name "sensor_FL_hip"
        }
        RotationalMotor {
          name "motor_FL_hip"
          maxTorque 100
        }
      ]
      endPoint Solid {
        translation 0.11363518317785334 0.10001502745056146 -0.05020268037207577
        rotation 8.442458891544338e-06 0.9999999999495134 -5.449580159126995e-06 1.0442512576683245
        children [
          HingeJoint {
            jointParameters HingeJointParameters {
              position -1.7714337106508364
              axis 0 1 0
              anchor 0 0 -0.1
              minStop -2.5
            }
            device [
              PositionSensor {
                name "sensor_FL_knee"
              }
              RotationalMotor {
                name "motor_FL_knee"
                maxTorque 100
              }
            ]
            endPoint Solid {
              translation 0.09799397503306471 0 -0.08007060318987141
              rotation 0 -0.9999999999999999 0 1.7714337106508364
              children [
                Shape {
                  appearance PBRAppearance {
                    baseColor 1 0 0
                  }
                  geometry Cylinder {
                    height 0.2
                    radius 0.015
                  }
                }
              ]
              boundingObject Shape {
                geometry Cylinder {
                  height 0.2
                  radius 0.015
                }
              }
              physics Physics {
                density -1
                mass 0.5
              }
              linearVelocity 0.00024285491207229681 -0.0006516427843544996 0.0021655172478334725
              angularVelocity 0.0071143783182697614 0.0014750193001153806 -2.6278733355978837e-05
            }
          }
          Shape {
            appearance PBRAppearance {
              baseColor 1 0 0
              baseColorMap ImageTexture {
              }
            }
            geometry Cylinder {
              height 0.2
              radius 0.02
            }
          }
        ]
        name "FL"
        boundingObject Shape {
          geometry Cylinder {
            height 0.2
            radius 0.02
          }
        }
        physics Physics {
          density -1
          mass 1
        }
        linearVelocity 0.00013977860265239182 -0.0015468309684644303 0.0026160176199551
        angularVelocity 0.007113986092508235 -0.004192053151815724 -8.500657871575099e-05
      }
    }
    HingeJoint {
      jointParameters HingeJointParameters {
        position 1.04434627889312
        axis 0 1 0
        anchor -0.2 -0.1 0
        minStop -1.5
        maxStop 1.5
      }
      device [
        PositionSensor {
          name "sensor_BR_hip"
        }
        RotationalMotor {
          name "motor_BR_hip"
          maxTorque 100
        }
      ]
      endPoint Solid {
        translation -0.28639024973175203 -0.10000001472150344 -0.05020637734427853
        rotation 8.621672211150315e-06 0.9999999999474141 -5.553244154072707e-06 1.0443453143202808
        children [
          HingeJoint {
            jointParameters HingeJointParameters {
              position -1.7716004334566464
              axis 0 1 0
              anchor 0 0 -0.1
              minStop -2.5
            }
            device [
              PositionSensor {
                name "sensor_BR_knee"
              }
              RotationalMotor {
                name "motor_BR_knee"
                maxTorque 100
              }
            ]
            endPoint Solid {
              translation 0.09799065096766978 0 -0.08005426554542142
              rotation 0 -0.9999999999999999 0 1.7716004334566464
              children [
                Shape {
                  appearance PBRAppearance {
                    baseColor 1 0 0
                  }
                  geometry Cylinder {
                    height 0.2
                    radius 0.015
                  }
                }
              ]
              boundingObject Shape {
                geometry Cylinder {
                  height 0.2
                  radius 0.015
                }
              }
              physics Physics {
                density -1
                mass 0.5
              }
              linearVelocity 0.0002954170637738977 -0.0005854084215470644 -0.0004840468658361638
              angularVelocity 0.007115727563163247 0.0022510081020824363 -1.800302300805611e-05
            }
          }
          Shape {
            appearance PBRAppearance {
              baseColor 1 0 0
            }
            geometry Cylinder {
              height 0.2
              radius 0.02
            }
          }
        ]
        name "BR"
        boundingObject Shape {
          geometry Cylinder {
            height 0.2
            radius 0.02
          }
        }
        physics Physics {
          density -1
          mass 1
        }
        linearVelocity 0.0001935993034899483 -0.0014850446858564556 9.20478041498704e-05
        angularVelocity 0.007114728423044534 -0.0051134634293229855 -9.470236659911522e-05
      }
    }
    HingeJoint {
      jointParameters HingeJointParameters {
        position 0.726889486603893
        axis 0 1 0
        anchor -0.2 0.1 0
        minStop -1.5
        maxStop 1.5
      }
      device [
        PositionSensor {
          name "sensor_BL_hip"
        }
        RotationalMotor {
          name "motor_BL_hip"
          maxTorque 100
        }
      ]
      endPoint Solid {
        translation -0.2663881973916914 0.0999999899577868 -0.07464951783953579
        rotation 1.2905583695886309e-05 0.9999999999005982 -5.678891574217017e-06 0.72688835049554
        children [
          HingeJoint {
            jointParameters HingeJointParameters {
              position -1.771704434380671
              axis 0 1 0
              anchor 0 0 -0.1
              minStop -2.5
            }
            device [
              PositionSensor {
                name "sensor_BL_knee"
              }
              RotationalMotor {
                name "motor_BL_knee"
                maxTorque 100
              }
            ]
            endPoint Solid {
              translation 0.09798857606291395 0 -0.08004407453506254
              rotation 0 -1 0 1.7717044343806712
              children [
                Shape {
                  appearance PBRAppearance {
                    baseColor 1 0 0
                  }
                  geometry Cylinder {
                    height 0.2
                    radius 0.015
                  }
                }
              ]
              boundingObject Shape {
                geometry Cylinder {
                  height 0.2
                  radius 0.015
                }
              }
              physics Physics {
                density -1
                mass 0.5
              }
              linearVelocity 0.00024691730417651387 -0.00043515652145060575 0.0010572997234401626
              angularVelocity 0.007115232479773517 0.004650339279592892 6.973652060273553e-06
            }
          }
          Shape {
            appearance PBRAppearance {
              baseColor 1 0 0
            }
            geometry Cylinder {
              height 0.2
              radius 0.02
            }
          }
        ]
        name "BL"
        boundingObject Shape {
          geometry Cylinder {
            height 0.2
            radius 0.02
          }
        }
        physics Physics {
          density -1
          mass 1
        }
        linearVelocity 0.00020544770098226257 -0.0013307438085054695 0.0017016253535773586
        angularVelocity 0.007114470513925782 -0.003683310732909349 -7.969846389658635e-05
      }
    }
    HingeJoint {
      jointParameters HingeJointParameters {
        position 0.7269774649490777
        axis 0 1 0
        anchor 0.2 -0.1 0
        minStop -1.5
        maxStop 1.5
      }
      device [
        PositionSensor {
          name "sensor_FR_hip"
        }
        RotationalMotor {
          name "motor_FR_hip"
          maxTorque 100
        }
      ]
      endPoint Solid {
        translation 0.13360077289801792 -0.10000002447426948 -0.07464870976531895
        rotation 1.2887770418448383e-05 0.9999999999008672 -5.671954850960184e-06 0.7269763229084014
        children [
          HingeJoint {
            jointParameters HingeJointParameters {
              position -1.7719050830860472
              axis 0 1 0
              anchor 0 0 -0.1
              minStop -2.5
            }
            device [
              PositionSensor {
                name "sensor_FR_knee"
              }
              RotationalMotor {
                name "motor_FR_knee"
                maxTorque 100
              }
            ]
            endPoint Solid {
              translation 0.09798456995982836 0 -0.08002441365597716
              rotation 0 -1 0 1.7719050830860472
              children [
                Shape {
                  appearance PBRAppearance {
                    baseColor 1 0 0
                  }
                  geometry Cylinder {
                    height 0.2
                    radius 0.015
                  }
                }
              ]
              boundingObject Shape {
                geometry Cylinder {
                  height 0.2
                  radius 0.015
                }
              }
              physics Physics {
                density -1
                mass 0.5
              }
              linearVelocity 0.00030713430712477156 -0.0004649689081643115 0.0004541384255327564
              angularVelocity 0.007114688645341099 0.005829084439209214 1.8864324250518756e-05
            }
          }
          Shape {
            appearance PBRAppearance {
              baseColor 1 0 0
            }
            geometry Cylinder {
              height 0.2
              radius 0.02
            }
          }
        ]
        name "FR"
        boundingObject Shape {
          geometry Cylinder {
            height 0.2
            radius 0.02
          }
        }
        physics Physics {
          density -1
          mass 1
        }
        linearVelocity 0.00025779278529649695 -0.0013602842339836072 0.0012530917209169635
        angularVelocity 0.007113974984923209 -0.004578782752096661 -8.9032147990946e-05
      }
    }
    Shape {
      appearance PBRAppearance {
        baseColor 0 0 0.498039
      }
      geometry Box {
        size 0.4 0.2 0.1
      }
    }
  ]
  boundingObject Shape {
    appearance PBRAppearance {
    }
    geometry Box {
      size 0.4 0.2 0.1
    }
  }
  physics Physics {
    density -1
    mass 5
  }
  controller "main_SMC_controller"
  linearVelocity -7.389904795181646e-05 -0.0018851933200703126 0.0017476909414802628
  angularVelocity 0.007114121018508237 -0.0025678438783761862 -6.822924394469176e-05
}
