#VRML_SIM R2025a utf8

EXTERNPROTO "https://raw.githubusercontent.com/cyberbotics/webots/R2023b/projects/objects/backgrounds/protos/TexturedBackground.proto"
EXTERNPROTO "https://raw.githubusercontent.com/cyberbotics/webots/R2023b/projects/objects/backgrounds/protos/TexturedBackgroundLight.proto"
EXTERNPROTO "https://raw.githubusercontent.com/cyberbotics/webots/R2023b/projects/objects/floors/protos/Floor.proto"

WorldInfo {
}
Viewpoint {
  orientation 0.057564777983269054 -0.2385195594703395 -0.9694300986073272 5.5732422517622755
  position -0.9629456648985033 -0.7473801423668136 0.4332687047119992
}
TexturedBackground {
}
TexturedBackgroundLight {
}
Floor {
}
Robot {
  translation -5.701153323107057e-08 -3.408495524703423e-07 0.3987703393296594
  rotation -1.4424437322604858e-05 -3.79389723271262e-05 0.999999999176285 2.9540908916860813
  children [
    InertialUnit {
      name "imu"
    }
    HingeJoint {
      jointParameters HingeJointParameters {
        position 0.785
        axis 0 1 0
        anchor 0.2 0.1 0
      }
      device [
        PositionSensor {
          name "sensor_FL_hip"
        }
        RotationalMotor {
          name "motor_FL_hip"
          maxTorque 50
        }
      ]
      endPoint Solid {
        translation 0.12939118963566654 0.10001502745056146 -0.07066531398216012
        rotation 1.1834549966987789e-05 0.9999999999141611 -5.623274826912417e-06 0.7849988658913235
        children [
          HingeJoint {
            jointParameters HingeJointParameters {
              position -1.57
              axis 0 1 0
              anchor 0 0 -0.1
            }
            device [
              PositionSensor {
                name "sensor_FL_knee"
              }
              RotationalMotor {
                name "motor_FL_knee"
                maxTorque 50
              }
            ]
            endPoint Solid {
              translation 0.09999996829309195 0 -0.1000796327639756
              rotation 0 -1 0 1.57
              children [
                Shape {
                  appearance PBRAppearance {
                    baseColor 1 0 0
                  }
                  geometry Cylinder {
                    height 0.2
                    radius 0.015
                  }
                }
              ]
              boundingObject Shape {
                geometry Cylinder {
                  height 0.2
                  radius 0.015
                }
              }
              physics Physics {
                density -1
                mass 0.5
              }
            }
          }
          Shape {
            appearance PBRAppearance {
              baseColor 1 0 0
              baseColorMap ImageTexture {
              }
            }
            geometry Cylinder {
              height 0.2
              radius 0.02
            }
          }
        ]
        name "FL"
        boundingObject Shape {
          geometry Cylinder {
            height 0.2
            radius 0.02
          }
        }
        physics Physics {
          density -1
          mass 1
        }
      }
    }
    HingeJoint {
      jointParameters HingeJointParameters {
        position 0.785
        axis 0 1 0
        anchor -0.2 -0.1 0
      }
      device [
        PositionSensor {
          name "sensor_BR_hip"
        }
        RotationalMotor {
          name "motor_BR_hip"
          maxTorque 50
        }
      ]
      endPoint Solid {
        translation -0.2706258097813032 -0.10000001472150344 -0.07068203850686382
        rotation 1.208461704156811e-05 0.9999999999105827 -5.726824088524209e-06 0.7849990354205572
        children [
          HingeJoint {
            jointParameters HingeJointParameters {
              position -1.57
              axis 0 1 0
              anchor 0 0 -0.1
            }
            device [
              PositionSensor {
                name "sensor_BR_knee"
              }
              RotationalMotor {
                name "motor_BR_knee"
                maxTorque 50
              }
            ]
            endPoint Solid {
              translation 0.09999996829318358 0 -0.10007963267107334
              rotation 0 -1 0 1.57
              children [
                Shape {
                  appearance PBRAppearance {
                    baseColor 1 0 0
                  }
                  geometry Cylinder {
                    height 0.2
                    radius 0.015
                  }
                }
              ]
              boundingObject Shape {
                geometry Cylinder {
                  height 0.2
                  radius 0.015
                }
              }
              physics Physics {
                density -1
                mass 0.5
              }
            }
          }
          Shape {
            appearance PBRAppearance {
              baseColor 1 0 0
            }
            geometry Cylinder {
              height 0.2
              radius 0.02
            }
          }
        ]
        name "BR"
        boundingObject Shape {
          geometry Cylinder {
            height 0.2
            radius 0.02
          }
        }
        physics Physics {
          density -1
          mass 1
        }
      }
    }
    HingeJoint {
      jointParameters HingeJointParameters {
        position 0.785
        axis 0 1 0
        anchor -0.2 0.1 0
      }
      device [
        PositionSensor {
          name "sensor_BL_hip"
        }
        RotationalMotor {
          name "motor_BL_hip"
          maxTorque 50
        }
      ]
      endPoint Solid {
        translation -0.2706116188571018 0.0999999899577868 -0.07066783249098041
        rotation 1.1836140420460717e-05 0.9999999999141369 -5.624227037950798e-06 0.7849988638813228
        children [
          HingeJoint {
            jointParameters HingeJointParameters {
              position -1.57
              axis 0 1 0
              anchor 0 0 -0.1
            }
            device [
              PositionSensor {
                name "sensor_BL_knee"
              }
              RotationalMotor {
                name "motor_BL_knee"
                maxTorque 50
              }
            ]
            endPoint Solid {
              translation 0.09999996829318275 0 -0.10007963267107334
              rotation 0 -1 0 1.57
              children [
                Shape {
                  appearance PBRAppearance {
                    baseColor 1 0 0
                  }
                  geometry Cylinder {
                    height 0.2
                    radius 0.015
                  }
                }
              ]
              boundingObject Shape {
                geometry Cylinder {
                  height 0.2
                  radius 0.015
                }
              }
              physics Physics {
                density -1
                mass 0.5
              }
            }
          }
          Shape {
            appearance PBRAppearance {
              baseColor 1 0 0
            }
            geometry Cylinder {
              height 0.2
              radius 0.02
            }
          }
        ]
        name "BL"
        boundingObject Shape {
          geometry Cylinder {
            height 0.2
            radius 0.02
          }
        }
        physics Physics {
          density -1
          mass 1
        }
      }
    }
    HingeJoint {
      jointParameters HingeJointParameters {
        position 0.785
        axis 0 1 0
        anchor 0.2 -0.1 0
      }
      device [
        PositionSensor {
          name "sensor_FR_hip"
        }
        RotationalMotor {
          name "motor_FR_hip"
          maxTorque 50
        }
      ]
      endPoint Solid {
        translation 0.12938363436622824 -0.10000002447426948 -0.07067259818377429
        rotation 1.182134149310962e-05 0.9999999999143503 -5.617406915663603e-06 0.784998857953978
        children [
          HingeJoint {
            jointParameters HingeJointParameters {
              position -1.57
              axis 0 1 0
              anchor 0 0 -0.1
            }
            device [
              PositionSensor {
                name "sensor_FR_knee"
              }
              RotationalMotor {
                name "motor_FR_knee"
                maxTorque 50
              }
            ]
            endPoint Solid {
              translation 0.09999996829318342 0 -0.10007963267107334
              rotation 0 -1 0 1.57
              children [
                Shape {
                  appearance PBRAppearance {
                    baseColor 1 0 0
                  }
                  geometry Cylinder {
                    height 0.2
                    radius 0.015
                  }
                }
              ]
              boundingObject Shape {
                geometry Cylinder {
                  height 0.2
                  radius 0.015
                }
              }
              physics Physics {
                density -1
                mass 0.5
              }
            }
          }
          Shape {
            appearance PBRAppearance {
              baseColor 1 0 0
            }
            geometry Cylinder {
              height 0.2
              radius 0.02
            }
          }
        ]
        name "FR"
        boundingObject Shape {
          geometry Cylinder {
            height 0.2
            radius 0.02
          }
        }
        physics Physics {
          density -1
          mass 1
        }
      }
    }
    Shape {
      appearance PBRAppearance {
        baseColor 0 0 0.498039
      }
      geometry Box {
        size 0.4 0.2 0.1
      }
    }
  ]
  boundingObject Shape {
    appearance PBRAppearance {
    }
    geometry Box {
      size 0.4 0.2 0.1
    }
  }
  physics Physics {
    density -1
    mass 5
  }
  controller "main_SMC_controller"
}
