#VRML_SIM R2023b utf8

EXTERNPROTO "https://raw.githubusercontent.com/cyberbotics/webots/R2023b/projects/objects/backgrounds/protos/TexturedBackground.proto"
EXTERNPROTO "https://raw.githubusercontent.com/cyberbotics/webots/R2023b/projects/objects/backgrounds/protos/TexturedBackgroundLight.proto"
EXTERNPROTO "https://raw.githubusercontent.com/cyberbotics/webots/R2023b/projects/objects/floors/protos/Floor.proto"

WorldInfo {
}
Viewpoint {
  orientation 0.15941088729475203 -0.5198198309006793 -0.8392708218532852 5.481299569524431
  position -3.5961866501263993 -1.5657007014893398 1.0894578977515779
}
TexturedBackground {
}
TexturedBackgroundLight {
}
Floor {
}
Robot {
  translation -2.137882695045748 -0.2601660742320729 0.3988492538642786
  rotation -1.3036703659420862e-05 -2.1089077483732793e-05 0.9999999996926476 2.954184510431345
  children [
    InertialUnit {
      name "imu"
    }
    HingeJoint {
      jointParameters HingeJointParameters {
        position 5.120362745548959e-10
        axis 0 1 0
        anchor 0.2 0.1 0
      }
      device [
        PositionSensor {
          name "sensor_FL_hip"
        }
        RotationalMotor {
          name "motor_FL_hip"
        }
      ]
      endPoint Solid {
        translation 0.20000017739710815 0.10001503345026475 -0.09998249727461243
        rotation 0.9923830745634789 -0.1122622125275409 -0.050725032857142166 1.0091640210505502e-05
        children [
          HingeJoint {
            jointParameters HingeJointParameters {
              position 4.269102690272453e-10
              axis 0 1 0
              anchor 0 0 -0.1
            }
            device [
              PositionSensor {
                name "sensor_FL_knee"
              }
              RotationalMotor {
                name "motor_FL_knee"
              }
            ]
            endPoint Solid {
              translation 1.4354658358538097e-10 0 -0.20000000000000046
              rotation 0 1 0 0
              children [
                Shape {
                  appearance PBRAppearance {
                    baseColor 1 0 0
                  }
                  geometry Cylinder {
                    height 0.2
                    radius 0.015
                  }
                }
              ]
              boundingObject Shape {
                geometry Cylinder {
                  height 0.2
                  radius 0.015
                }
              }
              physics Physics {
                density -1
                mass 0.5
              }
              linearVelocity -1.2959477144862953e-10 -2.9229559645810765e-11 5.105888683374552e-07
              angularVelocity -2.2682571338490167e-10 -1.3649932840658243e-09 7.396369264311e-10
            }
          }
          Shape {
            appearance PBRAppearance {
              baseColor 1 0 0
              baseColorMap ImageTexture {
              }
            }
            geometry Cylinder {
              height 0.2
              radius 0.02
            }
          }
        ]
        name "FL"
        boundingObject Shape {
          geometry Cylinder {
            height 0.2
            radius 0.02
          }
        }
        physics Physics {
        }
        linearVelocity -1.849733955512706e-10 -7.020563383260109e-11 2.3839115459702907e-07
        angularVelocity 6.202105004769413e-11 2.1148582676791198e-10 7.40425859216429e-10
      }
    }
    HingeJoint {
      jointParameters HingeJointParameters {
        position 7.003197527877664e-11
        axis 0 1 0
        anchor -0.2 -0.1 0
      }
      device [
        PositionSensor {
          name "sensor_BR_hip"
        }
        RotationalMotor {
          name "motor_BR_hip"
        }
      ]
      endPoint Solid {
        translation -0.200000021015809 -0.1 -0.09999991573771723
        rotation 0.9943821265695848 -0.09340823656691269 -0.04979043784111397 1.0278345301237155e-05
        children [
          HingeJoint {
            jointParameters HingeJointParameters {
              position 6.53657992308001e-07
              axis 0 1 0
              anchor 0 0 -0.1
            }
            device [
              PositionSensor {
                name "sensor_FL_knee"
              }
              RotationalMotor {
                name "motor_FL_knee"
              }
            ]
            endPoint Solid {
              translation -6.53657992307955e-08 0 -0.1999999999999787
              rotation 0 1 0 6.53615957482499e-07
              children [
                Shape {
                  appearance PBRAppearance {
                    baseColor 1 0 0
                  }
                  geometry Cylinder {
                    height 0.2
                    radius 0.015
                  }
                }
              ]
              boundingObject Shape {
                geometry Cylinder {
                  height 0.2
                  radius 0.015
                }
              }
              physics Physics {
                density -1
                mass 0.5
              }
              linearVelocity -2.082128169810809e-10 5.915618242464546e-11 5.104099759591997e-07
              angularVelocity -7.23804049293079e-10 -3.666033402617375e-09 7.395064912842655e-10
            }
          }
          Shape {
            appearance PBRAppearance {
              baseColor 1 0 0
            }
            geometry Cylinder {
              height 0.2
              radius 0.02
            }
          }
        ]
        name "BR"
        boundingObject Shape {
          geometry Cylinder {
            height 0.2
            radius 0.02
          }
        }
        physics Physics {
        }
        linearVelocity -3.8453619380384943e-10 1.5827135016998368e-10 2.3826574812480195e-07
        angularVelocity -8.746691969321281e-10 -4.521409819019939e-09 7.402107065283482e-10
      }
    }
    HingeJoint {
      jointParameters HingeJointParameters {
        position -2.2456757218423703e-09
        axis 0 1 0
        anchor -0.2 0.1 0
      }
      device [
        PositionSensor {
          name "sensor_BL_hip"
        }
        RotationalMotor {
          name "motor_BL_hip"
        }
      ]
      endPoint Solid {
        translation -0.20000002074681505 0.1 -0.09999999999999767
        rotation 0.9923240840005549 -0.11278381760846824 -0.05072201492566296 1.0093312286768911e-05
        children [
          HingeJoint {
            jointParameters HingeJointParameters {
              position 6.53686102703711e-07
              axis 0 1 0
              anchor 0 0 -0.1
            }
            device [
              PositionSensor {
                name "sensor_FL_knee"
              }
              RotationalMotor {
                name "motor_FL_knee"
              }
            ]
            endPoint Solid {
              translation -6.536861027032867e-08 0 -0.19999999999997786
              rotation 0 0.9999999999999999 0 6.53615957482499e-07
              children [
                Shape {
                  appearance PBRAppearance {
                    baseColor 1 0 0
                  }
                  geometry Cylinder {
                    height 0.2
                    radius 0.015
                  }
                }
              ]
              boundingObject Shape {
                geometry Cylinder {
                  height 0.2
                  radius 0.015
                }
              }
              physics Physics {
                density -1
                mass 0.5
              }
              linearVelocity -4.220958385901479e-12 2.151812193668555e-11 5.155259868843337e-07
              angularVelocity 1.2101336635524737e-10 7.870768260437373e-10 7.397354664197965e-10
            }
          }
          Shape {
            appearance PBRAppearance {
              baseColor 1 0 0
            }
            geometry Cylinder {
              height 0.2
              radius 0.02
            }
          }
        ]
        name "BL"
        boundingObject Shape {
          geometry Cylinder {
            height 0.2
            radius 0.02
          }
        }
        physics Physics {
        }
        linearVelocity 1.292803475915252e-11 8.340427542285709e-11 2.4082321354147975e-07
        angularVelocity 4.457603969269996e-10 2.4404368676004824e-09 7.405272874625567e-10
      }
    }
    HingeJoint {
      jointParameters HingeJointParameters {
        position -2.225745733412585e-09
        axis 0 1 0
        anchor 0.2 -0.1 0
      }
      device [
        PositionSensor {
          name "sensor_FR_hip"
        }
        RotationalMotor {
          name "motor_FR_hip"
        }
      ]
      endPoint Solid {
        translation 0.19999997925568874 -0.1 -0.09999999999999813
        rotation 0.9923228948946868 -0.11279430675693071 -0.05072195413281667 1.0091508192685196e-05
        children [
          HingeJoint {
            jointParameters HingeJointParameters {
              position 6.536808628523682e-07
              axis 0 1 0
              anchor 0 0 -0.1
            }
            device [
              PositionSensor {
                name "sensor_FL_knee"
              }
              RotationalMotor {
                name "motor_FL_knee"
              }
            ]
            endPoint Solid {
              translation -6.536808628523236e-08 0 -0.19999999999997864
              rotation 0 1 0 6.53615957482499e-07
              children [
                Shape {
                  appearance PBRAppearance {
                    baseColor 1 0 0
                  }
                  geometry Cylinder {
                    height 0.2
                    radius 0.015
                  }
                }
              ]
              boundingObject Shape {
                geometry Cylinder {
                  height 0.2
                  radius 0.015
                }
              }
              physics Physics {
                density -1
                mass 0.5
              }
              linearVelocity -7.283156785502328e-12 1.1921504902383904e-11 5.155475726042243e-07
              angularVelocity 1.9471555770870184e-10 7.446619435273175e-10 7.397360188330754e-10
            }
          }
          Shape {
            appearance PBRAppearance {
              baseColor 1 0 0
            }
            geometry Cylinder {
              height 0.2
              radius 0.02
            }
          }
        ]
        name "FR"
        boundingObject Shape {
          geometry Cylinder {
            height 0.2
            radius 0.02
          }
        }
        physics Physics {
        }
        linearVelocity -9.115325493966572e-11 -5.6899044649572226e-11 2.40870800746175e-07
        angularVelocity 4.845068575148766e-10 2.3574168327578024e-09 7.405254319596438e-10
      }
    }
    Shape {
      appearance PBRAppearance {
        baseColor 0 0 0.498039
      }
      geometry Box {
        size 0.4 0.2 0.1
      }
    }
  ]
  boundingObject Shape {
    appearance PBRAppearance {
    }
    geometry Box {
      size 0.4 0.2 0.1
    }
  }
  physics Physics {
  }
  controller "<none>"
}
